<?xml version="1.0" encoding="utf-8"?>
<robot name="cobot_nextup" xmlns:xacro="http://www.ros.org/wiki/xacro">
  
  <link name='world'>
  </link>

  <joint name="joint0" type="fixed">
    <origin xyz="0 0 0" rpy="0.0 0.0 0.0"/>
    <parent link="world"/>
    <child link="base_link"/>
  </joint>

  <!-- <joint name="joint10" type="fixed">
    <origin xyz="0.0 0.0 0.0" rpy="0.0 0.0 0.0"/>
    <parent link="world"/>
    <child link="robot_base_link"/>
  </joint> -->

  <link name="base_link">
    <inertial>
      <origin xyz="0 0 0" rpy="0 0 0" />
      <mass value="400" />
      <inertia ixx="800" ixy="0.0" ixz="0.0" iyy="800" iyz="0.0" izz="800" />
    </inertial>
    <visual>
      <geometry>
        <box size="0.6 0.6 1.2" />
      </geometry>
      <origin xyz="0 0 0.6" rpy="0 0 0" />
      <material name="grey">
        <color rgba="0.5 0.5 0.5 1" />
      </material>
    </visual>
    <collision>
      <geometry>
        <box size="0.6 0.6 1.2" />
      </geometry>
      <origin xyz="0 0 0.6" rpy="0 0 0" />
    </collision>
  </link>

  <link name="lift_link">
      <inertial>
        <origin xyz="0 0 0" rpy="0 0 0" />
        <mass value="50" />
        <inertia ixx="20" ixy="0.0" ixz="0.0" iyy="20" iyz="0.0" izz="20" />
      </inertial>
      <visual>
        <geometry>
          <box size="0.5 2 0.1" />
        </geometry>
        <origin xyz="0 0 0" rpy="0 0 0" />
        <material name="blue">
          <color rgba="0 0 1 1" />
        </material>
      </visual>
      <collision>
        <geometry>
          <box size="0.5 2 0.1" />
        </geometry>
        <origin xyz="0 0 0" rpy="0 0 0" />
      </collision>
  </link>

  <joint name="lift_joint" type="prismatic">
    <parent link="base_link"/>
    <child link="lift_link"/>
    <origin xyz="0 1 0.05" rpy="0 0 3.14"/>
    <axis xyz="0 0 1" />
    <limit lower="0.0" upper="1.0" effort="1000" velocity="1.0" />
    <!-- <dynamics damping="50.0" friction="10.0"/> -->
  </joint>

  <joint name="lift_link-base_link" type="fixed"> 
    <parent link="lift_link"/>
    <child link="robot_base_link"/>
    <origin rpy="0 0 3.141592653589793" xyz="0 -0.8 0.05"/>
  </joint>
  

  <link
    name="robot_base_link">
    <inertial>
      <origin
        xyz="-9.1637E-05 0.039944 0.056986"
        rpy="0 0 0" />
      <mass
        value="4" />
      <inertia
        ixx="0.015337"
        ixy="-1.0396E-06"
        ixz="1.3702E-06"
        iyy="0.014167"
        iyz="0.00053877"
        izz="0.011044" />
    </inertial>
    <visual>
      <origin
        xyz="0 0 0"
        rpy="0 0 0" />
      <geometry>
        <mesh
          filename="package://new_cobot_moveit/meshes/base_link.STL" />
      </geometry>
      <material
        name="">
        <color
          rgba="0.79216 0.81961 0.93333 1" />
      </material>
    </visual>
    <collision>
      <origin
        xyz="0 0 0"
        rpy="0 0 0" />
      <geometry>
        <mesh
          filename="package://new_cobot_moveit/meshes/base_link.STL" />
      </geometry>
    </collision>
  </link>
  <link
    name="link1">
    <inertial>
      <origin
        xyz="-9.1637E-05 0.039944 0.056986"
        rpy="0 0 0" />
      <mass
        value="2.2626" />
      <inertia
        ixx="0.015337"
        ixy="-1.0396E-06"
        ixz="1.3702E-06"
        iyy="0.014167"
        iyz="0.00053877"
        izz="0.011044" />
    </inertial>
    <visual>
      <origin
        xyz="0 0 0"
        rpy="0 0 0" />
      <geometry>
        <mesh
          filename="package://new_cobot_moveit/meshes/link1.STL" />
      </geometry>
      <material
        name="">
        <color
          rgba="0.79216 0.81961 0.93333 1" />
      </material>
    </visual>
    <collision>
      <origin
        xyz="0 0 0"
        rpy="0 0 0" />
      <geometry>
        <mesh
          filename="package://new_cobot_moveit/meshes/link1.STL" />
      </geometry>
    </collision>
  </link>
  <joint
    name="joint1"
    type="revolute">
    <origin
      xyz="0 -0.019668 0.263"
      rpy="0 0 0" />
    <parent
      link="robot_base_link" />
    <child
      link="link1" />
    <axis
      xyz="0 0 1" />
    <limit
      lower="-3.14"
      upper="3.14"
      effort="1000"
      velocity="1" />
  </joint>
  <link
    name="link2">
    <inertial>
      <origin
        xyz="-4.3407E-05 0.22867 0.015143"
        rpy="0 0 0" />
      <mass
        value="2.1612" />
      <inertia
        ixx="0.045655"
        ixy="-1.1181E-06"
        ixz="6.3917E-07"
        iyy="0.0035179"
        iyz="-0.00022473"
        izz="0.047984" />
    </inertial>
    <visual>
      <origin
        xyz="0 0 0"
        rpy="0 0 0" />
      <geometry>
        <mesh
          filename="package://new_cobot_moveit/meshes/link2.STL" />
      </geometry>
      <material
        name="">
        <color
          rgba="0.79216 0.81961 0.93333 1" />
      </material>
    </visual>
    <collision>
      <origin
        xyz="0 0 0"
        rpy="0 0 0" />
      <geometry>
        <mesh
          filename="package://new_cobot_moveit/meshes/link2.STL" />
      </geometry>
    </collision>
  </link>
  <joint
    name="joint2"
    type="revolute">
    <origin
      xyz="0 0.173 0.08"
      rpy="1.5708 0 3.1416" />
    <parent
      link="link1" />
    <child
      link="link2" />
    <axis
      xyz="0 0 1" />
    <limit
      lower="-3.14"
      upper="3.14"
      effort="1000"
      velocity="1" />
  </joint>
  <link
    name="link3">
    <inertial>
      <origin
        xyz="2.3468E-05 0.20434 0.064783"
        rpy="0 0 0" />
      <mass
        value="1.6881" />
      <inertia
        ixx="0.028434"
        ixy="-1.3905E-06"
        ixz="-1.4394E-07"
        iyy="0.002102"
        iyz="-6.9448E-05"
        izz="0.029626" />
    </inertial>
    <visual>
      <origin
        xyz="0 0 0"
        rpy="0 0 0" />
      <geometry>
        <mesh
          filename="package://new_cobot_moveit/meshes/link3.STL" />
      </geometry>
      <material
        name="">
        <color
          rgba="0.79216 0.81961 0.93333 1" />
      </material>
    </visual>
    <collision>
      <origin
        xyz="0 0 0"
        rpy="0 0 0" />
      <geometry>
        <mesh
          filename="package://new_cobot_moveit/meshes/link3.STL" />
      </geometry>
    </collision>
  </link>
  <joint
    name="joint3"
    type="revolute">
    <origin
      xyz="0 0.4 -0.055"
      rpy="3.1416 0 -3.1416" />
    <parent
      link="link2" />
    <child
      link="link3" />
    <axis
      xyz="0 0 1" />
    <limit
      lower="-3.14"
      upper="3.14"
      effort="1000"
      velocity="1" />
  </joint>
  <link
    name="link4">
    <inertial>
      <origin
        xyz="-8.7633E-07 0.053539 0.064823"
        rpy="0 0 0" />
      <mass
        value="0.86109" />
      <inertia
        ixx="0.0015448"
        ixy="1.4103E-08"
        ixz="-5.1075E-09"
        iyy="0.0015335"
        iyz="-7.6172E-06"
        izz="0.0016958" />
    </inertial>
    <visual>
      <origin
        xyz="0 0 0"
        rpy="0 0 0" />
      <geometry>
        <mesh
          filename="package://new_cobot_moveit/meshes/link4.STL" />
      </geometry>
      <material
        name="">
        <color
          rgba="0.79216 0.81961 0.93333 1" />
      </material>
    </visual>
    <collision>
      <origin
        xyz="0 0 0"
        rpy="0 0 0" />
      <geometry>
        <mesh
          filename="package://new_cobot_moveit/meshes/link4.STL" />
      </geometry>
    </collision>
  </link>
  <joint
    name="joint4"
    type="revolute">
    <origin
      xyz="0 0.35 -0.019"
      rpy="3.1416 0 3.1416" />
    <parent
      link="link3" />
    <child
      link="link4" />
    <axis
      xyz="0 0 1" />
    <limit
      lower="-3.14"
      upper="3.14"
      effort="1000"
      velocity="1" />
  </joint>
  <link
    name="link5">
    <inertial>
      <origin
        xyz="-9.2508E-07 0.017174 0.042592"
        rpy="0 0 0" />
      <mass
        value="0.57767" />
      <inertia
        ixx="0.0021492"
        ixy="5.3445E-09"
        ixz="-9.9996E-09"
        iyy="0.0013344"
        iyz="-2.2102E-05"
        izz="0.0022237" />
    </inertial>
    <visual>
      <origin
        xyz="0 0 0"
        rpy="0 0 0" />
      <geometry>
        <mesh
          filename="package://new_cobot_moveit/meshes/link5.STL" />
      </geometry>
      <material
        name="">
        <color
          rgba="0.79216 0.81961 0.93333 1" />
      </material>
    </visual>
    <collision>
      <origin
        xyz="0 0 0"
        rpy="0 0 0" />
      <geometry>
        <mesh
          filename="package://new_cobot_moveit/meshes/link5.STL" />
      </geometry>
    </collision>
  </link>
  <joint
    name="joint5"
    type="revolute">
    <origin
      xyz="0 0.178 0.08"
      rpy="1.5708 0 3.1416" />
    <parent
      link="link4" />
    <child
      link="link5" />
    <axis
      xyz="0 0 1" />
    <limit
      lower="-3.14"
      upper="3.14"
      effort="1000"
      velocity="1" />
  </joint>
  <link
    name="link6">
    <inertial>
      <origin
        xyz="-7.8437E-10 -1.3776E-10 -0.035114"
        rpy="0 0 0" />
      <mass
        value="0.25388" />
      <inertia
        ixx="0.00015464"
        ixy="8.4622E-13"
        ixz="-4.6301E-14"
        iyy="0.00015464"
        iyz="-1.9438E-14"
        izz="0.00028441" />
    </inertial>
    <visual>
      <origin
        xyz="0 0 0"
        rpy="0 0 0" />
      <geometry>
        <mesh
          filename="package://new_cobot_moveit/meshes/link6.STL" />
      </geometry>
      <material
        name="">
        <color
          rgba="0.79216 0.81961 0.93333 1" />
      </material>
    </visual>
    <collision>
      <origin
        xyz="0 0 0"
        rpy="0 0 0" />
      <geometry>
        <mesh
          filename="package://new_cobot_moveit/meshes/link6.STL" />
      </geometry>
    </collision>
  </link>
  <joint
    name="joint6"
    type="revolute">
    <origin
      xyz="0 0.148 0.0725"
      rpy="1.5708 0 3.1416" />
    <parent
      link="link5" />
    <child
      link="link6" />
    <axis
      xyz="0 0 1" />
    <limit
      lower="-3.14"
      upper="3.14"
      effort="1000"
      velocity="1" />
  </joint>

</robot>
